#VRML_SIM R2020b utf8
WorldInfo {
  info [
    "Thanks to Mehdi Ghanavati, Shahid Chamran University"
  ]
  title "Omni-wheels"
  basicTimeStep 20
  coordinateSystem "NUE"
}
Viewpoint {
  orientation 0.000560265639968791 0.710633350011683 0.703562312772355 3.1427244464641397
  position 1.0292821589641656 9.643421244849746 1.7767301903283288
  follow "four"
  followType "None"
}
TexturedBackground {
}
TexturedBackgroundLight {
}
Floor {
  translation 1 0 2
  size 5 5
  tileSize 2 2
}
WoodenBox {
  translation 1 0.3 2
  name "wooden box(1)"
}
DEF four Robot {
  translation 0 0.04 0
  children [
    InertialUnit {
      name "inertial_unit"
    }
    GPS {
    }
    DEF RealBaseTrans Transform {
      children [
        DEF RealBaseShape Shape {
          appearance Appearance {
            material Material {
              ambientIntensity 1
              diffuseColor 1 1 1
              emissiveColor 0.21 0.21 0.21
              shininess 0.21
              specularColor 0.88 0.88 0.88
            }
          }
          geometry IndexedFaceSet {
            coord Coordinate {
              point [
                -0.34 0 -0.22, -0.34 0 -0.076655, -0.34 0 0.076655, -0.34 0 0.22, -0.34 0.02 -0.22, -0.34 0.02 -0.076655, -0.34 0.02 0.076655, -0.34 0.02 0.22, -0.338177 0 -0.240838, -0.338177 0 0.240838, -0.338177 0.02 -0.240838, -0.338177 0.02 0.240838, -0.332763 0 -0.261042, -0.332763 0 0.261042, -0.332763 0.02 -0.261042, -0.332763 0.02 0.261042, -0.33 0 -0.266968, -0.33 0 -0.076655, -0.33 0 0.076655, -0.33 0 0.266968, -0.33 0.02 -0.266968, -0.33 0.02 -0.076655, -0.33 0.02 0.076655, -0.33 0.02 0.266968, -0.323923 0 -0.28, -0.323923 0 0.28, -0.323923 0.02 -0.28, -0.323923 0.02 0.28, -0.32 0 -0.22, -0.32 0 -0.086655, -0.32 0 -0.066655, -0.32 0 0.066655, -0.32 0 0.086655, -0.32 0 0.22, -0.32 0.02 -0.22, -0.32 0.02 -0.086655, -0.32 0.02 -0.066655, -0.32 0.02 0.066655, -0.32 0.02 0.086655, -0.32 0.02 0.22, -0.318481 0 -0.237365, -0.318481 0 0.237365, -0.318481 0.02 -0.237365, -0.318481 0.02 0.237365, -0.313969 0 -0.254202, -0.313969 0 0.254202, -0.313969 0.02 -0.254202, -0.313969 0.02 0.254202, -0.311925 0 -0.297135, -0.311925 0 0.297135, -0.311925 0.02 -0.297135, -0.311925 0.02 0.297135, -0.306603 0 -0.27, -0.306603 0 0.27, -0.306603 0.02 -0.27, -0.306603 0.02 0.27, -0.297135 0 -0.311925, -0.297135 0 0.311925, -0.297135 0.02 -0.311925, -0.297135 0.02 0.311925, -0.296604 0 -0.284279, -0.296604 0 0.284279, -0.296604 0.02 -0.284279, -0.296604 0.02 0.284279, -0.284279 0 -0.296604, -0.284279 0 0.296604, -0.284279 0.02 -0.296604, -0.284279 0.02 0.296604, -0.28 0 -0.323923, -0.28 0 0.323923, -0.28 0.02 -0.323923, -0.28 0.02 0.323923, -0.27 0 -0.306603, -0.27 0 0.306603, -0.27 0.02 -0.306603, -0.27 0.02 0.306603, -0.266968 0 0.33, -0.266968 0.02 0.33, -0.261042 0 -0.332763, -0.261042 0 0.332763, -0.261042 0.02 -0.332763, -0.261042 0.02 0.332763, -0.254202 0 -0.313969, -0.254202 0 0.313969, -0.254202 0.02 -0.313969, -0.254202 0.02 0.313969, -0.240838 0 -0.338177, -0.240838 0 0.338177, -0.240838 0.02 -0.338177, -0.240838 0.02 0.338177, -0.237365 0 -0.318481, -0.237365 0 0.318481, -0.237365 0.02 -0.318481, -0.237365 0.02 0.318481, -0.22 0 -0.34, -0.22 0 -0.32, -0.22 0 0.32, -0.22 0 0.34, -0.22 0.02 -0.34, -0.22 0.02 -0.32, -0.22 0.02 0.32, -0.22 0.02 0.34, -0.086655 0 -0.32, -0.086655 0 -0.086655, -0.086655 0 0.086655, -0.086655 0 0.32, -0.086655 0.02 -0.32, -0.086655 0.02 -0.086655, -0.086655 0.02 0.086655, -0.086655 0.02 0.32, -0.076655 0 -0.34, -0.076655 0 -0.076655, -0.076655 0 -0.066655, -0.076655 0 0.066655, -0.076655 0 0.076655, -0.076655 0 0.33, -0.076655 0 0.34, -0.076655 0.02 -0.34, -0.076655 0.02 -0.076655, -0.076655 0.02 -0.066655, -0.076655 0.02 0.066655, -0.076655 0.02 0.076655, -0.076655 0.02 0.33, -0.076655 0.02 0.34, -0.066655 0 -0.32, -0.066655 0 -0.086655, -0.066655 0 0.086655, -0.066655 0 0.32, -0.066655 0.02 -0.32, -0.066655 0.02 -0.086655, -0.066655 0.02 0.086655, -0.066655 0.02 0.32, 0.066655 0 -0.32, 0.066655 0 -0.086655, 0.066655 0 0.086655, 0.066655 0 0.32, 0.066655 0.02 -0.32, 0.066655 0.02 -0.086655, 0.066655 0.02 0.086655, 0.066655 0.02 0.32, 0.076655 0 -0.34, 0.076655 0 -0.076655, 0.076655 0 -0.066655, 0.076655 0 0.066655, 0.076655 0 0.076655, 0.076655 0 0.33, 0.076655 0 0.34, 0.076655 0.02 -0.34, 0.076655 0.02 -0.076655, 0.076655 0.02 -0.066655, 0.076655 0.02 0.066655, 0.076655 0.02 0.076655, 0.076655 0.02 0.33, 0.076655 0.02 0.34, 0.086655 0 -0.32, 0.086655 0 -0.086655, 0.086655 0 0.086655, 0.086655 0 0.32, 0.086655 0.02 -0.32, 0.086655 0.02 -0.086655, 0.086655 0.02 0.086655, 0.086655 0.02 0.32, 0.22 0 -0.34, 0.22 0 -0.32, 0.22 0 0.32, 0.22 0 0.34, 0.22 0.02 -0.34, 0.22 0.02 -0.32, 0.22 0.02 0.32, 0.22 0.02 0.34, 0.237365 0 -0.318481, 0.237365 0 0.318481, 0.237365 0.02 -0.318481, 0.237365 0.02 0.318481, 0.240838 0 -0.338177, 0.240838 0 0.338177, 0.240838 0.02 -0.338177, 0.240838 0.02 0.338177, 0.254202 0 -0.313969, 0.254202 0 0.313969, 0.254202 0.02 -0.313969, 0.254202 0.02 0.313969, 0.261042 0 -0.332763, 0.261042 0 0.332763, 0.261042 0.02 -0.332763, 0.261042 0.02 0.332763, 0.266968 0 0.33, 0.266968 0.02 0.33, 0.27 0 -0.306603, 0.27 0 0.306603, 0.27 0.02 -0.306603, 0.27 0.02 0.306603, 0.28 0 -0.323923, 0.28 0 0.323923, 0.28 0.02 -0.323923, 0.28 0.02 0.323923, 0.284279 0 -0.296604, 0.284279 0 0.296604, 0.284279 0.02 -0.296604, 0.284279 0.02 0.296604, 0.296604 0 -0.284279, 0.296604 0 0.284279, 0.296604 0.02 -0.284279, 0.296604 0.02 0.284279, 0.297135 0 -0.311925, 0.297135 0 0.311925, 0.297135 0.02 -0.311925, 0.297135 0.02 0.311925, 0.306603 0 -0.27, 0.306603 0 0.27, 0.306603 0.02 -0.27, 0.306603 0.02 0.27, 0.311925 0 -0.297135, 0.311925 0 0.297135, 0.311925 0.02 -0.297135, 0.311925 0.02 0.297135, 0.313969 0 -0.254202, 0.313969 0 0.254202, 0.313969 0.02 -0.254202, 0.313969 0.02 0.254202, 0.318481 0 -0.237365, 0.318481 0 0.237365, 0.318481 0.02 -0.237365, 0.318481 0.02 0.237365, 0.32 0 -0.22, 0.32 0 -0.086655, 0.32 0 -0.066655, 0.32 0 0.066655, 0.32 0 0.086655, 0.32 0 0.22, 0.32 0.02 -0.22, 0.32 0.02 -0.086655, 0.32 0.02 -0.066655, 0.32 0.02 0.066655, 0.32 0.02 0.086655, 0.32 0.02 0.22, 0.323923 0 -0.28, 0.323923 0 0.28, 0.323923 0.02 -0.28, 0.323923 0.02 0.28, 0.332763 0 -0.261042, 0.332763 0 0.261042, 0.332763 0.02 -0.261042, 0.332763 0.02 0.261042, 0.338177 0 -0.240838, 0.338177 0 0.240838, 0.338177 0.02 -0.240838, 0.338177 0.02 0.240838, 0.34 0 -0.22, 0.34 0 -0.076655, 0.34 0 0.076655, 0.34 0 0.22, 0.34 0.02 -0.22, 0.34 0.02 -0.076655, 0.34 0.02 0.076655, 0.34 0.02 0.22
              ]
            }
            normal Normal {
              vector [
                -1 0 0, -0.984808 0 -0.173648, -0.984808 0 0.173648, -0.939693 0 -0.34202, -0.939693 0 0.34202, -0.919674 0 -0.392683, -0.919674 0 0.392683, -0.866025 0 -0.5, -0.866025 0 0.5, -0.766044 0 -0.642788, -0.766044 0 0.642788, -0.642788 0 -0.766044, -0.642788 0 0.766044, -0.5 0 -0.866025, -0.5 0 0.866025, -0.392683 0 0.919674, -0.34202 0 -0.939693, -0.34202 0 0.939693, -0.173648 0 -0.984808, -0.173648 0 0.984808, 0 -1 0, 0 0 -1, 0 0 1, 0 1 0, 0.173648 0 -0.984808, 0.173648 0 0.984808, 0.34202 0 -0.939693, 0.34202 0 0.939693, 0.392683 0 0.919674, 0.5 0 -0.866025, 0.5 0 0.866025, 0.642788 0 -0.766044, 0.642788 0 0.766044, 0.766044 0 -0.642788, 0.766044 0 0.642788, 0.866025 0 -0.5, 0.866025 0 0.5, 0.939693 0 -0.34202, 0.939693 0 0.34202, 0.984808 0 -0.173648, 0.984808 0 0.173648, 1 0 0
              ]
            }
            coordIndex [
              150, 120, 151, -1, 151, 120, 121, -1, 150, 151, 233, -1, 233, 151, 254, -1, 233, 254, 232, -1, 232, 254, 253, -1, 232, 253, 149, -1, 149, 253, 148, -1, 149, 148, 118, -1, 121, 120, 22, -1, 22, 120, 37, -1, 22, 37, 21, -1, 21, 37, 36, -1, 21, 36, 118, -1, 118, 36, 119, -1, 118, 119, 149, -1, 77, 81, 89, -1, 23, 43, 39, -1, 89, 101, 77, -1, 77, 101, 122, -1, 77, 122, 100, -1, 22, 38, 121, -1, 121, 38, 108, -1, 121, 108, 122, -1, 122, 108, 109, -1, 122, 109, 100, -1, 100, 93, 77, -1, 77, 93, 85, -1, 77, 85, 71, -1, 71, 85, 75, -1, 71, 75, 59, -1, 59, 75, 67, -1, 59, 67, 51, -1, 51, 67, 63, -1, 51, 63, 27, -1, 27, 63, 55, -1, 27, 55, 23, -1, 23, 55, 47, -1, 23, 47, 43, -1, 11, 15, 7, -1, 7, 15, 23, -1, 7, 23, 22, -1, 22, 23, 39, -1, 22, 39, 38, -1, 34, 20, 21, -1, 34, 42, 20, -1, 20, 42, 46, -1, 20, 46, 26, -1, 26, 46, 54, -1, 26, 54, 50, -1, 50, 54, 62, -1, 50, 62, 58, -1, 58, 62, 66, -1, 58, 66, 70, -1, 70, 66, 74, -1, 70, 74, 80, -1, 80, 74, 84, -1, 80, 84, 88, -1, 88, 84, 92, -1, 88, 92, 98, -1, 98, 92, 99, -1, 98, 99, 117, -1, 117, 99, 106, -1, 117, 106, 118, -1, 118, 106, 107, -1, 118, 107, 21, -1, 21, 107, 35, -1, 21, 35, 34, -1, 198, 206, 190, -1, 190, 206, 194, -1, 190, 194, 180, -1, 180, 194, 184, -1, 180, 184, 172, -1, 172, 184, 176, -1, 172, 176, 167, -1, 167, 176, 166, -1, 167, 166, 158, -1, 158, 166, 147, -1, 158, 147, 159, -1, 159, 147, 148, -1, 159, 148, 231, -1, 231, 148, 253, -1, 231, 253, 230, -1, 230, 253, 252, -1, 230, 252, 222, -1, 222, 252, 246, -1, 222, 246, 218, -1, 218, 246, 242, -1, 218, 242, 210, -1, 210, 242, 238, -1, 210, 238, 202, -1, 202, 238, 214, -1, 202, 214, 198, -1, 198, 214, 206, -1, 181, 173, 187, -1, 187, 173, 168, -1, 187, 168, 152, -1, 152, 168, 161, -1, 152, 161, 151, -1, 151, 161, 160, -1, 151, 160, 254, -1, 254, 160, 234, -1, 254, 234, 255, -1, 255, 234, 235, -1, 255, 235, 247, -1, 247, 235, 223, -1, 247, 223, 243, -1, 243, 223, 219, -1, 243, 219, 239, -1, 239, 219, 211, -1, 239, 211, 215, -1, 215, 211, 203, -1, 215, 203, 207, -1, 207, 203, 199, -1, 207, 199, 195, -1, 195, 199, 191, -1, 195, 191, 187, -1, 187, 191, 181, -1, 136, 147, 128, -1, 128, 147, 117, -1, 128, 117, 129, -1, 129, 117, 118, -1, 129, 118, 137, -1, 137, 118, 148, -1, 137, 148, 136, -1, 136, 148, 147, -1, 14, 10, 20, -1, 20, 10, 4, -1, 20, 4, 21, -1, 21, 4, 5, -1, 21, 5, 22, -1, 22, 5, 6, -1, 22, 6, 7, -1, 138, 151, 130, -1, 130, 151, 121, -1, 130, 121, 131, -1, 131, 121, 122, -1, 131, 122, 139, -1, 139, 122, 152, -1, 139, 152, 138, -1, 138, 152, 151, -1, 101, 123, 122, -1, 122, 123, 153, -1, 122, 153, 152, -1, 152, 153, 169, -1, 152, 169, 187, -1, 187, 169, 177, -1, 187, 177, 185, -1, 87, 79, 76, -1, 142, 141, 226, -1, 226, 141, 249, -1, 226, 249, 227, -1, 227, 249, 250, -1, 227, 250, 143, -1, 143, 250, 144, -1, 143, 144, 113, -1, 113, 144, 114, -1, 113, 114, 31, -1, 31, 114, 18, -1, 31, 18, 30, -1, 30, 18, 17, -1, 30, 17, 112, -1, 112, 17, 111, -1, 112, 111, 142, -1, 142, 111, 141, -1, 164, 186, 145, -1, 164, 171, 186, -1, 186, 171, 179, -1, 186, 179, 193, -1, 193, 179, 189, -1, 193, 189, 205, -1, 205, 189, 197, -1, 205, 197, 213, -1, 213, 197, 201, -1, 213, 201, 237, -1, 237, 201, 209, -1, 237, 209, 241, -1, 241, 209, 217, -1, 241, 217, 245, -1, 245, 217, 221, -1, 245, 221, 251, -1, 251, 221, 229, -1, 251, 229, 250, -1, 250, 229, 228, -1, 250, 228, 144, -1, 144, 228, 156, -1, 144, 156, 145, -1, 145, 156, 157, -1, 145, 157, 164, -1, 178, 182, 188, -1, 188, 182, 192, -1, 188, 192, 196, -1, 196, 192, 204, -1, 196, 204, 200, -1, 200, 204, 212, -1, 200, 212, 208, -1, 208, 212, 236, -1, 208, 236, 216, -1, 216, 236, 240, -1, 216, 240, 220, -1, 220, 240, 244, -1, 220, 244, 224, -1, 224, 244, 248, -1, 224, 248, 225, -1, 225, 248, 249, -1, 225, 249, 155, -1, 155, 249, 141, -1, 155, 141, 154, -1, 154, 141, 140, -1, 154, 140, 163, -1, 163, 140, 162, -1, 163, 162, 170, -1, 170, 162, 174, -1, 170, 174, 178, -1, 178, 174, 182, -1, 44, 40, 16, -1, 16, 40, 28, -1, 16, 28, 17, -1, 17, 28, 29, -1, 17, 29, 111, -1, 111, 29, 103, -1, 111, 103, 110, -1, 110, 103, 102, -1, 110, 102, 94, -1, 94, 102, 95, -1, 94, 95, 86, -1, 86, 95, 90, -1, 86, 90, 78, -1, 78, 90, 82, -1, 78, 82, 68, -1, 68, 82, 72, -1, 68, 72, 56, -1, 56, 72, 64, -1, 56, 64, 48, -1, 48, 64, 60, -1, 48, 60, 24, -1, 24, 60, 52, -1, 24, 52, 16, -1, 16, 52, 44, -1, 13, 9, 3, -1, 96, 105, 115, -1, 13, 3, 19, -1, 19, 3, 18, -1, 19, 18, 33, -1, 115, 105, 114, -1, 114, 105, 104, -1, 114, 104, 18, -1, 18, 104, 32, -1, 18, 32, 33, -1, 76, 91, 96, -1, 33, 41, 19, -1, 19, 41, 45, -1, 19, 45, 25, -1, 25, 45, 53, -1, 25, 53, 49, -1, 49, 53, 61, -1, 49, 61, 57, -1, 57, 61, 65, -1, 57, 65, 69, -1, 69, 65, 73, -1, 69, 73, 76, -1, 76, 73, 83, -1, 76, 83, 91, -1, 96, 115, 76, -1, 76, 115, 97, -1, 76, 97, 87, -1, 183, 175, 186, -1, 186, 175, 165, -1, 186, 165, 145, -1, 145, 165, 146, -1, 145, 146, 115, -1, 115, 146, 116, -1, 115, 116, 97, -1, 135, 145, 127, -1, 127, 145, 115, -1, 127, 115, 126, -1, 126, 115, 114, -1, 126, 114, 134, -1, 134, 114, 144, -1, 134, 144, 135, -1, 135, 144, 145, -1, 3, 2, 18, -1, 18, 2, 1, -1, 18, 1, 17, -1, 17, 1, 0, -1, 17, 0, 16, -1, 16, 0, 8, -1, 16, 8, 12, -1, 125, 111, 124, -1, 124, 111, 110, -1, 124, 110, 132, -1, 132, 110, 140, -1, 132, 140, 133, -1, 133, 140, 141, -1, 133, 141, 125, -1, 125, 141, 111, -1, 165, 169, 146, -1, 146, 169, 153, -1, 146, 153, 116, -1, 116, 153, 123, -1, 116, 123, 97, -1, 97, 123, 101, -1, 169, 165, 175, -1, 169, 175, 177, -1, 177, 175, 183, -1, 177, 183, 185, -1, 185, 183, 187, -1, 187, 183, 186, -1, 187, 186, 195, -1, 186, 193, 195, -1, 195, 193, 205, -1, 195, 205, 207, -1, 207, 205, 213, -1, 207, 213, 215, -1, 215, 213, 237, -1, 215, 237, 239, -1, 239, 237, 241, -1, 239, 241, 243, -1, 243, 241, 245, -1, 243, 245, 247, -1, 247, 245, 251, -1, 247, 251, 255, -1, 248, 252, 249, -1, 249, 252, 253, -1, 249, 253, 250, -1, 250, 253, 254, -1, 250, 254, 251, -1, 251, 254, 255, -1, 252, 248, 244, -1, 252, 244, 246, -1, 246, 244, 240, -1, 246, 240, 242, -1, 242, 240, 236, -1, 242, 236, 238, -1, 238, 236, 212, -1, 238, 212, 214, -1, 214, 212, 204, -1, 214, 204, 206, -1, 206, 204, 192, -1, 206, 192, 194, -1, 194, 192, 182, -1, 194, 182, 184, -1, 184, 182, 174, -1, 184, 174, 176, -1, 176, 174, 162, -1, 176, 162, 166, -1, 94, 98, 110, -1, 110, 98, 117, -1, 110, 117, 140, -1, 140, 117, 147, -1, 140, 147, 162, -1, 162, 147, 166, -1, 98, 94, 86, -1, 98, 86, 88, -1, 88, 86, 78, -1, 88, 78, 80, -1, 80, 78, 68, -1, 80, 68, 70, -1, 70, 68, 56, -1, 70, 56, 58, -1, 58, 56, 48, -1, 58, 48, 50, -1, 50, 48, 24, -1, 50, 24, 26, -1, 26, 24, 20, -1, 20, 24, 16, -1, 20, 16, 14, -1, 16, 12, 14, -1, 14, 12, 8, -1, 14, 8, 10, -1, 10, 8, 0, -1, 10, 0, 4, -1, 3, 7, 2, -1, 2, 7, 6, -1, 2, 6, 1, -1, 1, 6, 5, -1, 1, 5, 0, -1, 0, 5, 4, -1, 108, 38, 104, -1, 104, 38, 32, -1, 109, 108, 105, -1, 105, 108, 104, -1, 100, 109, 96, -1, 96, 109, 105, -1, 100, 96, 93, -1, 93, 96, 91, -1, 93, 91, 85, -1, 85, 91, 83, -1, 85, 83, 75, -1, 75, 83, 73, -1, 75, 73, 67, -1, 67, 73, 65, -1, 67, 65, 63, -1, 63, 65, 61, -1, 63, 61, 55, -1, 55, 61, 53, -1, 55, 53, 47, -1, 47, 53, 45, -1, 47, 45, 43, -1, 43, 45, 41, -1, 43, 41, 39, -1, 39, 41, 33, -1, 107, 106, 103, -1, 103, 106, 102, -1, 35, 107, 29, -1, 29, 107, 103, -1, 34, 35, 28, -1, 28, 35, 29, -1, 34, 28, 42, -1, 42, 28, 40, -1, 42, 40, 46, -1, 46, 40, 44, -1, 46, 44, 54, -1, 54, 44, 52, -1, 54, 52, 62, -1, 62, 52, 60, -1, 62, 60, 66, -1, 66, 60, 64, -1, 66, 64, 74, -1, 74, 64, 72, -1, 74, 72, 84, -1, 84, 72, 82, -1, 84, 82, 92, -1, 92, 82, 90, -1, 92, 90, 99, -1, 99, 90, 95, -1, 129, 137, 125, -1, 125, 137, 133, -1, 128, 129, 124, -1, 124, 129, 125, -1, 136, 128, 132, -1, 132, 128, 124, -1, 159, 231, 155, -1, 155, 231, 225, -1, 158, 159, 154, -1, 154, 159, 155, -1, 167, 158, 163, -1, 163, 158, 154, -1, 167, 163, 172, -1, 172, 163, 170, -1, 172, 170, 180, -1, 180, 170, 178, -1, 180, 178, 190, -1, 190, 178, 188, -1, 190, 188, 198, -1, 198, 188, 196, -1, 198, 196, 202, -1, 202, 196, 200, -1, 202, 200, 210, -1, 210, 200, 208, -1, 210, 208, 218, -1, 218, 208, 216, -1, 218, 216, 222, -1, 222, 216, 220, -1, 222, 220, 230, -1, 230, 220, 224, -1, 138, 130, 134, -1, 134, 130, 126, -1, 139, 138, 135, -1, 135, 138, 134, -1, 131, 139, 127, -1, 127, 139, 135, -1, 160, 161, 156, -1, 156, 161, 157, -1, 234, 160, 228, -1, 228, 160, 156, -1, 235, 234, 229, -1, 229, 234, 228, -1, 235, 229, 223, -1, 223, 229, 221, -1, 223, 221, 219, -1, 219, 221, 217, -1, 219, 217, 211, -1, 211, 217, 209, -1, 211, 209, 203, -1, 203, 209, 201, -1, 203, 201, 199, -1, 199, 201, 197, -1, 199, 197, 191, -1, 191, 197, 189, -1, 191, 189, 181, -1, 181, 189, 179, -1, 181, 179, 173, -1, 173, 179, 171, -1, 173, 171, 168, -1, 168, 171, 164, -1, 38, 39, 32, -1, 32, 39, 33, -1, 106, 99, 102, -1, 102, 99, 95, -1, 137, 136, 133, -1, 133, 136, 132, -1, 231, 230, 225, -1, 225, 230, 224, -1, 130, 131, 126, -1, 126, 131, 127, -1, 161, 168, 157, -1, 157, 168, 164, -1, 7, 3, 9, -1, 7, 9, 11, -1, 11, 9, 13, -1, 11, 13, 15, -1, 15, 13, 23, -1, 23, 13, 19, -1, 23, 19, 27, -1, 19, 25, 27, -1, 27, 25, 49, -1, 27, 49, 51, -1, 51, 49, 57, -1, 51, 57, 59, -1, 59, 57, 69, -1, 59, 69, 71, -1, 71, 69, 77, -1, 77, 69, 76, -1, 77, 76, 81, -1, 76, 79, 81, -1, 81, 79, 87, -1, 81, 87, 89, -1, 89, 87, 97, -1, 89, 97, 101, -1, 233, 232, 227, -1, 227, 232, 226, -1, 226, 232, 142, -1, 142, 232, 149, -1, 142, 149, 112, -1, 112, 149, 119, -1, 112, 119, 30, -1, 30, 119, 36, -1, 36, 37, 30, -1, 30, 37, 31, -1, 31, 37, 113, -1, 113, 37, 120, -1, 113, 120, 143, -1, 143, 120, 150, -1, 143, 150, 227, -1, 227, 150, 233, -1
            ]
            normalIndex [
              23, 23, 23, -1, 23, 23, 23, -1, 23, 23, 23, -1, 23, 23, 23, -1, 23, 23, 23, -1, 23, 23, 23, -1, 23, 23, 23, -1, 23, 23, 23, -1, 23, 23, 23, -1, 23, 23, 23, -1, 23, 23, 23, -1, 23, 23, 23, -1, 23, 23, 23, -1, 23, 23, 23, -1, 23, 23, 23, -1, 23, 23, 23, -1, 23, 23, 23, -1, 23, 23, 23, -1, 23, 23, 23, -1, 23, 23, 23, -1, 23, 23, 23, -1, 23, 23, 23, -1, 23, 23, 23, -1, 23, 23, 23, -1, 23, 23, 23, -1, 23, 23, 23, -1, 23, 23, 23, -1, 23, 23, 23, -1, 23, 23, 23, -1, 23, 23, 23, -1, 23, 23, 23, -1, 23, 23, 23, -1, 23, 23, 23, -1, 23, 23, 23, -1, 23, 23, 23, -1, 23, 23, 23, -1, 23, 23, 23, -1, 23, 23, 23, -1, 23, 23, 23, -1, 23, 23, 23, -1, 23, 23, 23, -1, 23, 23, 23, -1, 23, 23, 23, -1, 23, 23, 23, -1, 23, 23, 23, -1, 23, 23, 23, -1, 23, 23, 23, -1, 23, 23, 23, -1, 23, 23, 23, -1, 23, 23, 23, -1, 23, 23, 23, -1, 23, 23, 23, -1, 23, 23, 23, -1, 23, 23, 23, -1, 23, 23, 23, -1, 23, 23, 23, -1, 23, 23, 23, -1, 23, 23, 23, -1, 23, 23, 23, -1, 23, 23, 23, -1, 23, 23, 23, -1, 23, 23, 23, -1, 23, 23, 23, -1, 23, 23, 23, -1, 23, 23, 23, -1, 23, 23, 23, -1, 23, 23, 23, -1, 23, 23, 23, -1, 23, 23, 23, -1, 23, 23, 23, -1, 23, 23, 23, -1, 23, 23, 23, -1, 23, 23, 23, -1, 23, 23, 23, -1, 23, 23, 23, -1, 23, 23, 23, -1, 23, 23, 23, -1, 23, 23, 23, -1, 23, 23, 23, -1, 23, 23, 23, -1, 23, 23, 23, -1, 23, 23, 23, -1, 23, 23, 23, -1, 23, 23, 23, -1, 23, 23, 23, -1, 23, 23, 23, -1, 23, 23, 23, -1, 23, 23, 23, -1, 23, 23, 23, -1, 23, 23, 23, -1, 23, 23, 23, -1, 23, 23, 23, -1, 23, 23, 23, -1, 23, 23, 23, -1, 23, 23, 23, -1, 23, 23, 23, -1, 23, 23, 23, -1, 23, 23, 23, -1, 23, 23, 23, -1, 23, 23, 23, -1, 23, 23, 23, -1, 23, 23, 23, -1, 23, 23, 23, -1, 23, 23, 23, -1, 23, 23, 23, -1, 23, 23, 23, -1, 23, 23, 23, -1, 23, 23, 23, -1, 23, 23, 23, -1, 23, 23, 23, -1, 23, 23, 23, -1, 23, 23, 23, -1, 23, 23, 23, -1, 23, 23, 23, -1, 23, 23, 23, -1, 23, 23, 23, -1, 23, 23, 23, -1, 23, 23, 23, -1, 23, 23, 23, -1, 23, 23, 23, -1, 23, 23, 23, -1, 23, 23, 23, -1, 23, 23, 23, -1, 23, 23, 23, -1, 23, 23, 23, -1, 23, 23, 23, -1, 23, 23, 23, -1, 23, 23, 23, -1, 23, 23, 23, -1, 23, 23, 23, -1, 23, 23, 23, -1, 23, 23, 23, -1, 23, 23, 23, -1, 23, 23, 23, -1, 23, 23, 23, -1, 23, 23, 23, -1, 23, 23, 23, -1, 23, 23, 23, -1, 23, 23, 23, -1, 23, 23, 23, -1, 23, 23, 23, -1, 23, 23, 23, -1, 23, 23, 23, -1, 23, 23, 23, -1, 23, 23, 23, -1, 23, 23, 23, -1, 23, 23, 23, -1, 23, 23, 23, -1, 20, 20, 20, -1, 20, 20, 20, -1, 20, 20, 20, -1, 20, 20, 20, -1, 20, 20, 20, -1, 20, 20, 20, -1, 20, 20, 20, -1, 20, 20, 20, -1, 20, 20, 20, -1, 20, 20, 20, -1, 20, 20, 20, -1, 20, 20, 20, -1, 20, 20, 20, -1, 20, 20, 20, -1, 20, 20, 20, -1, 20, 20, 20, -1, 20, 20, 20, -1, 20, 20, 20, -1, 20, 20, 20, -1, 20, 20, 20, -1, 20, 20, 20, -1, 20, 20, 20, -1, 20, 20, 20, -1, 20, 20, 20, -1, 20, 20, 20, -1, 20, 20, 20, -1, 20, 20, 20, -1, 20, 20, 20, -1, 20, 20, 20, -1, 20, 20, 20, -1, 20, 20, 20, -1, 20, 20, 20, -1, 20, 20, 20, -1, 20, 20, 20, -1, 20, 20, 20, -1, 20, 20, 20, -1, 20, 20, 20, -1, 20, 20, 20, -1, 20, 20, 20, -1, 20, 20, 20, -1, 20, 20, 20, -1, 20, 20, 20, -1, 20, 20, 20, -1, 20, 20, 20, -1, 20, 20, 20, -1, 20, 20, 20, -1, 20, 20, 20, -1, 20, 20, 20, -1, 20, 20, 20, -1, 20, 20, 20, -1, 20, 20, 20, -1, 20, 20, 20, -1, 20, 20, 20, -1, 20, 20, 20, -1, 20, 20, 20, -1, 20, 20, 20, -1, 20, 20, 20, -1, 20, 20, 20, -1, 20, 20, 20, -1, 20, 20, 20, -1, 20, 20, 20, -1, 20, 20, 20, -1, 20, 20, 20, -1, 20, 20, 20, -1, 20, 20, 20, -1, 20, 20, 20, -1, 20, 20, 20, -1, 20, 20, 20, -1, 20, 20, 20, -1, 20, 20, 20, -1, 20, 20, 20, -1, 20, 20, 20, -1, 20, 20, 20, -1, 20, 20, 20, -1, 20, 20, 20, -1, 20, 20, 20, -1, 20, 20, 20, -1, 20, 20, 20, -1, 20, 20, 20, -1, 20, 20, 20, -1, 20, 20, 20, -1, 20, 20, 20, -1, 20, 20, 20, -1, 20, 20, 20, -1, 20, 20, 20, -1, 20, 20, 20, -1, 20, 20, 20, -1, 20, 20, 20, -1, 20, 20, 20, -1, 20, 20, 20, -1, 20, 20, 20, -1, 20, 20, 20, -1, 20, 20, 20, -1, 20, 20, 20, -1, 20, 20, 20, -1, 20, 20, 20, -1, 20, 20, 20, -1, 20, 20, 20, -1, 20, 20, 20, -1, 20, 20, 20, -1, 20, 20, 20, -1, 20, 20, 20, -1, 20, 20, 20, -1, 20, 20, 20, -1, 20, 20, 20, -1, 20, 20, 20, -1, 20, 20, 20, -1, 20, 20, 20, -1, 20, 20, 20, -1, 20, 20, 20, -1, 20, 20, 20, -1, 20, 20, 20, -1, 20, 20, 20, -1, 20, 20, 20, -1, 20, 20, 20, -1, 20, 20, 20, -1, 20, 20, 20, -1, 20, 20, 20, -1, 20, 20, 20, -1, 20, 20, 20, -1, 20, 20, 20, -1, 20, 20, 20, -1, 20, 20, 20, -1, 20, 20, 20, -1, 20, 20, 20, -1, 20, 20, 20, -1, 20, 20, 20, -1, 20, 20, 20, -1, 20, 20, 20, -1, 20, 20, 20, -1, 20, 20, 20, -1, 20, 20, 20, -1, 20, 20, 20, -1, 20, 20, 20, -1, 20, 20, 20, -1, 20, 20, 20, -1, 20, 20, 20, -1, 20, 20, 20, -1, 20, 20, 20, -1, 20, 20, 20, -1, 20, 20, 20, -1, 20, 20, 20, -1, 20, 20, 20, -1, 20, 20, 20, -1, 20, 20, 20, -1, 20, 20, 20, -1, 20, 20, 20, -1, 20, 20, 20, -1, 22, 22, 22, -1, 22, 22, 22, -1, 22, 22, 22, -1, 22, 22, 22, -1, 22, 22, 22, -1, 22, 22, 22, -1, 22, 22, 25, -1, 22, 25, 25, -1, 25, 25, 27, -1, 25, 27, 27, -1, 27, 27, 28, -1, 28, 27, 28, -1, 28, 28, 30, -1, 28, 30, 30, -1, 30, 30, 32, -1, 30, 32, 32, -1, 32, 32, 34, -1, 32, 34, 34, -1, 34, 34, 36, -1, 34, 36, 36, -1, 36, 36, 38, -1, 36, 38, 38, -1, 38, 38, 40, -1, 38, 40, 40, -1, 40, 40, 41, -1, 40, 41, 41, -1, 41, 41, 41, -1, 41, 41, 41, -1, 41, 41, 41, -1, 41, 41, 41, -1, 41, 41, 41, -1, 41, 41, 41, -1, 41, 41, 39, -1, 41, 39, 39, -1, 39, 39, 37, -1, 39, 37, 37, -1, 37, 37, 35, -1, 37, 35, 35, -1, 35, 35, 33, -1, 35, 33, 33, -1, 33, 33, 31, -1, 33, 31, 31, -1, 31, 31, 29, -1, 31, 29, 29, -1, 29, 29, 26, -1, 29, 26, 26, -1, 26, 26, 24, -1, 26, 24, 24, -1, 24, 24, 21, -1, 24, 21, 21, -1, 21, 21, 21, -1, 21, 21, 21, -1, 21, 21, 21, -1, 21, 21, 21, -1, 21, 21, 21, -1, 21, 21, 21, -1, 21, 21, 18, -1, 21, 18, 18, -1, 18, 18, 16, -1, 18, 16, 16, -1, 16, 16, 13, -1, 16, 13, 13, -1, 13, 13, 11, -1, 13, 11, 11, -1, 11, 11, 9, -1, 11, 9, 9, -1, 9, 9, 7, -1, 9, 7, 7, -1, 7, 7, 5, -1, 5, 7, 5, -1, 5, 5, 3, -1, 5, 3, 3, -1, 3, 3, 1, -1, 3, 1, 1, -1, 1, 1, 0, -1, 1, 0, 0, -1, 0, 0, 0, -1, 0, 0, 0, -1, 0, 0, 0, -1, 0, 0, 0, -1, 0, 0, 0, -1, 0, 0, 0, -1, 22, 22, 22, -1, 22, 22, 22, -1, 0, 0, 0, -1, 0, 0, 0, -1, 21, 21, 21, -1, 21, 21, 21, -1, 21, 21, 24, -1, 24, 21, 24, -1, 24, 24, 26, -1, 26, 24, 26, -1, 26, 26, 29, -1, 29, 26, 29, -1, 29, 29, 31, -1, 31, 29, 31, -1, 31, 31, 33, -1, 33, 31, 33, -1, 33, 33, 35, -1, 35, 33, 35, -1, 35, 35, 37, -1, 37, 35, 37, -1, 37, 37, 39, -1, 39, 37, 39, -1, 39, 39, 41, -1, 41, 39, 41, -1, 0, 0, 0, -1, 0, 0, 0, -1, 21, 21, 21, -1, 21, 21, 21, -1, 41, 41, 41, -1, 41, 41, 41, -1, 41, 41, 40, -1, 40, 41, 40, -1, 40, 40, 38, -1, 38, 40, 38, -1, 38, 38, 36, -1, 36, 38, 36, -1, 36, 36, 34, -1, 34, 36, 34, -1, 34, 34, 32, -1, 32, 34, 32, -1, 32, 32, 30, -1, 30, 32, 30, -1, 30, 30, 27, -1, 27, 30, 27, -1, 27, 27, 25, -1, 25, 27, 25, -1, 25, 25, 22, -1, 22, 25, 22, -1, 21, 21, 21, -1, 21, 21, 21, -1, 41, 41, 41, -1, 41, 41, 41, -1, 22, 22, 22, -1, 22, 22, 22, -1, 21, 21, 21, -1, 21, 21, 21, -1, 41, 41, 41, -1, 41, 41, 41, -1, 22, 22, 22, -1, 22, 22, 22, -1, 22, 22, 19, -1, 19, 22, 19, -1, 19, 19, 17, -1, 17, 19, 17, -1, 17, 17, 14, -1, 14, 17, 14, -1, 14, 14, 12, -1, 12, 14, 12, -1, 12, 12, 10, -1, 10, 12, 10, -1, 10, 10, 8, -1, 8, 10, 8, -1, 8, 8, 4, -1, 4, 8, 4, -1, 4, 4, 2, -1, 2, 4, 2, -1, 2, 2, 0, -1, 0, 2, 0, -1, 22, 22, 22, -1, 22, 22, 22, -1, 0, 0, 0, -1, 0, 0, 0, -1, 21, 21, 21, -1, 21, 21, 21, -1, 41, 41, 41, -1, 41, 41, 41, -1, 22, 22, 22, -1, 22, 22, 22, -1, 0, 0, 0, -1, 0, 0, 0, -1, 0, 0, 1, -1, 1, 0, 1, -1, 1, 1, 3, -1, 3, 1, 3, -1, 3, 3, 7, -1, 7, 3, 7, -1, 7, 7, 9, -1, 9, 7, 9, -1, 9, 9, 11, -1, 11, 9, 11, -1, 11, 11, 13, -1, 13, 11, 13, -1, 13, 13, 16, -1, 16, 13, 16, -1, 16, 16, 18, -1, 18, 16, 18, -1, 18, 18, 21, -1, 21, 18, 21, -1, 41, 41, 41, -1, 41, 41, 41, -1, 22, 22, 22, -1, 22, 22, 22, -1, 0, 0, 0, -1, 0, 0, 0, -1, 0, 0, 0, -1, 0, 0, 0, -1, 41, 41, 41, -1, 41, 41, 41, -1, 21, 21, 21, -1, 21, 21, 21, -1, 0, 0, 2, -1, 0, 2, 2, -1, 2, 2, 4, -1, 2, 4, 4, -1, 4, 4, 6, -1, 6, 4, 6, -1, 6, 6, 8, -1, 6, 8, 8, -1, 8, 8, 10, -1, 8, 10, 10, -1, 10, 10, 12, -1, 10, 12, 12, -1, 12, 12, 14, -1, 12, 14, 14, -1, 14, 14, 15, -1, 15, 14, 15, -1, 15, 15, 17, -1, 15, 17, 17, -1, 17, 17, 19, -1, 17, 19, 19, -1, 19, 19, 22, -1, 19, 22, 22, -1, 0, 0, 0, -1, 0, 0, 0, -1, 22, 22, 22, -1, 22, 22, 22, -1, 22, 22, 22, -1, 22, 22, 22, -1, 22, 22, 22, -1, 22, 22, 22, -1, 41, 41, 41, -1, 41, 41, 41, -1, 21, 21, 21, -1, 21, 21, 21, -1, 21, 21, 21, -1, 21, 21, 21, -1, 21, 21, 21, -1, 21, 21, 21, -1
            ]
          }
        }
      ]
    }
    DEF SOLID1 Solid {
      translation 0 0.02 0
      rotation 0 1 0 -0.7853853071795864
      children [
        DEF WHEEL1 HingeJoint {
          jointParameters HingeJointParameters {
            position 1.40089e-08
            axis 0 0 -1
            anchor 0 0 1
          }
          device [
            RotationalMotor {
              name "wheel1"
              maxVelocity 100
            }
          ]
          endPoint Solid {
            translation 0 0 0.33000000000000007
            rotation 0 0 -1 0
            children [
              DEF cobo Transform {
                translation 0 0 0.02
                rotation 0 0 1 0.3927003061004253
                children [
                  DEF sr1 HingeJoint {
                    jointParameters HingeJointParameters {
                      position -6.352517592459877e-05
                      anchor 0 0.05 0.02
                    }
                    endPoint Solid {
                      translation 0 0.05 0.02
                      rotation -1 0 0 6.352517242818773e-05
                      children [
                        DEF r1 Transform {
                          rotation 0 0 1 1.5708
                          children [
                            DEF SMALL_WHEEL_SHAPE Shape {
                              appearance PBRAppearance {
                                baseColor 1 0.752941 0.796078
                                roughness 1
                                metalness 0
                              }
                              geometry Cylinder {
                                height 0.02
                                radius 0.01
                              }
                            }
                          ]
                        }
                      ]
                      name "sr1(1)"
                      boundingObject USE r1
                      physics Physics {
                        density -1
                        mass 0.1
                      }
                    }
                  }
                  DEF sr2 HingeJoint {
                    jointParameters HingeJointParameters {
                      position -4.654748554568171e-05
                      axis 0.707107 0.707107 0
                      anchor -0.03535 0.03535 0.02
                    }
                    endPoint Solid {
                      translation -0.03535 0.03535 0.02
                      rotation -0.7071067811865476 -0.7071067811865476 0 4.65474878204196e-05
                      children [
                        DEF r2 Transform {
                          rotation 0 0 1 2.27
                          children [
                            USE SMALL_WHEEL_SHAPE
                          ]
                        }
                      ]
                      name "sr2(1)"
                      boundingObject USE r2
                      physics Physics {
                        density -1
                        mass 0.1
                      }
                    }
                  }
                  DEF sr3 HingeJoint {
                    jointParameters HingeJointParameters {
                      position -0.04103525323229831
                      anchor 0 -0.05 0.02
                    }
                    endPoint Solid {
                      translation 0 -0.05 0.02
                      rotation -1 0 0 0.04103525323229323
                      children [
                        DEF r3 Transform {
                          rotation 0 0 1 1.5708
                          children [
                            USE SMALL_WHEEL_SHAPE
                          ]
                        }
                      ]
                      name "sr3(1)"
                      boundingObject USE r3
                      physics Physics {
                        density -1
                        mass 0.1
                      }
                    }
                  }
                  DEF sr4 HingeJoint {
                    jointParameters HingeJointParameters {
                      position -4.6557209329991446e-05
                      axis 0.707107 0.707107 0
                      anchor 0.03535 -0.03535 0.02
                    }
                    endPoint Solid {
                      translation 0.03535 -0.03535 0.02
                      rotation -0.7071067811865476 -0.7071067811865476 0 4.655720863842534e-05
                      children [
                        DEF r4 Transform {
                          rotation 0 0 1 2.27
                          children [
                            USE SMALL_WHEEL_SHAPE
                          ]
                        }
                      ]
                      name "sr4(1)"
                      boundingObject USE r4
                      physics Physics {
                        density -1
                        mass 0.1
                      }
                    }
                  }
                  DEF sr5 HingeJoint {
                    jointParameters HingeJointParameters {
                      position -2.025100852343402e-06
                      axis 0 1 0
                      anchor -0.05 0 0.02
                    }
                    endPoint Solid {
                      translation -0.05 0 0.02
                      rotation 0 -1 0 2.0250233983230487e-06
                      children [
                        DEF r5 Transform {
                          children [
                            USE SMALL_WHEEL_SHAPE
                          ]
                        }
                      ]
                      name "sr5(1)"
                      boundingObject USE r5
                      physics Physics {
                        density -1
                        mass 0.1
                      }
                    }
                  }
                  DEF sr6 HingeJoint {
                    jointParameters HingeJointParameters {
                      position -2.025101108733244e-06
                      axis 0 1 0
                      anchor 0.05 0 0.02
                    }
                    endPoint Solid {
                      translation 0.05 0 0.02
                      rotation 0 -1 0 2.0250233983230487e-06
                      children [
                        DEF r6 Transform {
                          children [
                            USE SMALL_WHEEL_SHAPE
                          ]
                        }
                      ]
                      name "sr6(1)"
                      boundingObject USE r6
                      physics Physics {
                        density -1
                        mass 0.1
                      }
                    }
                  }
                  DEF sr7 HingeJoint {
                    jointParameters HingeJointParameters {
                      position 4.4894304667585086e-05
                      axis -0.707107 0.707107 0
                      anchor -0.03535 -0.03535 0.02
                    }
                    endPoint Solid {
                      translation -0.03535 -0.03535 0.02
                      rotation -0.7071067811865476 0.7071067811865476 0 4.4894307868471914e-05
                      children [
                        DEF r7 Transform {
                          rotation 0 0 1 0.76
                          children [
                            USE SMALL_WHEEL_SHAPE
                          ]
                        }
                      ]
                      name "sr7(1)"
                      boundingObject USE r7
                      physics Physics {
                        density -1
                        mass 0.1
                      }
                    }
                  }
                  DEF sr8 HingeJoint {
                    jointParameters HingeJointParameters {
                      position 4.488925281233993e-05
                      axis -0.707107 0.707107 0
                      anchor 0.03535 0.03535 0.02
                    }
                    endPoint Solid {
                      translation 0.03535 0.03535 0.02
                      rotation -0.7071067811865476 0.7071067811865476 0 4.488925283201575e-05
                      children [
                        DEF r8 Transform {
                          rotation 0 0 1 0.76
                          children [
                            USE SMALL_WHEEL_SHAPE
                          ]
                        }
                      ]
                      name "sr8(1)"
                      boundingObject USE r8
                      physics Physics {
                        density -1
                        mass 0.1
                      }
                    }
                  }
                  DEF WHEEL_TRANS Transform {
                    translation 0 0 0.02
                    rotation 1 0 0 1.5708
                    children [
                      DEF WHEEL_SHAPE Shape {
                        appearance PBRAppearance {
                          baseColor 0.678431 0.847059 0.901961
                          roughness 1
                          metalness 0
                        }
                        geometry Cylinder {
                          height 0.02
                          radius 0.05
                          subdivision 20
                        }
                      }
                    ]
                  }
                ]
              }
              DEF sr1 HingeJoint {
                jointParameters HingeJointParameters {
                  position -6.352517592459877e-05
                  anchor 0 0.05 0.02
                }
                endPoint Solid {
                  translation 0 0.05 0.02
                  rotation -1 0 0 6.352517242818773e-05
                  children [
                    DEF r1 Transform {
                      rotation 0 0 1 1.5708
                      children [
                        DEF SMALL_WHEEL_SHAPE Shape {
                          appearance PBRAppearance {
                            baseColor 1 0.752941 0.796078
                            roughness 1
                            metalness 0
                          }
                          geometry Cylinder {
                            height 0.02
                            radius 0.01
                          }
                        }
                      ]
                    }
                  ]
                  name "sr1"
                  boundingObject USE r1
                  physics Physics {
                    density -1
                    mass 0.1
                  }
                }
              }
              DEF sr2 HingeJoint {
                jointParameters HingeJointParameters {
                  position -4.654748554568171e-05
                  axis 0.707107 0.707107 0
                  anchor -0.03535 0.03535 0.02
                }
                endPoint Solid {
                  translation -0.03535 0.03535 0.02
                  rotation -0.7071067811865476 -0.7071067811865476 0 4.65474878204196e-05
                  children [
                    DEF r2 Transform {
                      rotation 0 0 1 2.27
                      children [
                        USE SMALL_WHEEL_SHAPE
                      ]
                    }
                  ]
                  name "sr2"
                  boundingObject USE r2
                  physics Physics {
                    density -1
                    mass 0.1
                  }
                }
              }
              DEF sr3 HingeJoint {
                jointParameters HingeJointParameters {
                  position -0.04103525323229831
                  anchor 0 -0.05 0.02
                }
                endPoint Solid {
                  translation 0 -0.05 0.02
                  rotation -1 0 0 0.04103525323229323
                  children [
                    DEF r3 Transform {
                      rotation 0 0 1 1.5708
                      children [
                        USE SMALL_WHEEL_SHAPE
                      ]
                    }
                  ]
                  name "sr3"
                  boundingObject USE r3
                  physics Physics {
                    density -1
                    mass 0.1
                  }
                }
              }
              DEF sr4 HingeJoint {
                jointParameters HingeJointParameters {
                  position -4.6557209329991446e-05
                  axis 0.707107 0.707107 0
                  anchor 0.03535 -0.03535 0.02
                }
                endPoint Solid {
                  translation 0.03535 -0.03535 0.02
                  rotation -0.7071067811865476 -0.7071067811865476 0 4.655720863842534e-05
                  children [
                    DEF r4 Transform {
                      rotation 0 0 1 2.27
                      children [
                        USE SMALL_WHEEL_SHAPE
                      ]
                    }
                  ]
                  name "sr4"
                  boundingObject USE r4
                  physics Physics {
                    density -1
                    mass 0.1
                  }
                }
              }
              DEF sr5 HingeJoint {
                jointParameters HingeJointParameters {
                  position -2.025100852343402e-06
                  axis 0 1 0
                  anchor -0.05 0 0.02
                }
                endPoint Solid {
                  translation -0.05 0 0.02
                  rotation 0 -1 0 2.0250233983230487e-06
                  children [
                    DEF r5 Transform {
                      children [
                        USE SMALL_WHEEL_SHAPE
                      ]
                    }
                  ]
                  name "sr5"
                  boundingObject USE r5
                  physics Physics {
                    density -1
                    mass 0.1
                  }
                }
              }
              DEF sr6 HingeJoint {
                jointParameters HingeJointParameters {
                  position -2.025101108733244e-06
                  axis 0 1 0
                  anchor 0.05 0 0.02
                }
                endPoint Solid {
                  translation 0.05 0 0.02
                  rotation 0 -1 0 2.0250233983230487e-06
                  children [
                    DEF r6 Transform {
                      children [
                        USE SMALL_WHEEL_SHAPE
                      ]
                    }
                  ]
                  name "sr6"
                  boundingObject USE r6
                  physics Physics {
                    density -1
                    mass 0.1
                  }
                }
              }
              DEF sr7 HingeJoint {
                jointParameters HingeJointParameters {
                  position 4.4894304667585086e-05
                  axis -0.707107 0.707107 0
                  anchor -0.03535 -0.03535 0.02
                }
                endPoint Solid {
                  translation -0.03535 -0.03535 0.02
                  rotation -0.7071067811865476 0.7071067811865476 0 4.4894307868471914e-05
                  children [
                    DEF r7 Transform {
                      rotation 0 0 1 0.76
                      children [
                        USE SMALL_WHEEL_SHAPE
                      ]
                    }
                  ]
                  name "sr7"
                  boundingObject USE r7
                  physics Physics {
                    density -1
                    mass 0.1
                  }
                }
              }
              DEF sr8 HingeJoint {
                jointParameters HingeJointParameters {
                  position 4.488925281233993e-05
                  axis -0.707107 0.707107 0
                  anchor 0.03535 0.03535 0.02
                }
                endPoint Solid {
                  translation 0.03535 0.03535 0.02
                  rotation -0.7071067811865476 0.7071067811865476 0 4.488925283201575e-05
                  children [
                    DEF r8 Transform {
                      rotation 0 0 1 0.76
                      children [
                        USE SMALL_WHEEL_SHAPE
                      ]
                    }
                  ]
                  name "sr8"
                  boundingObject USE r8
                  physics Physics {
                    density -1
                    mass 0.1
                  }
                }
              }
              DEF WHEEL_TRANS Transform {
                translation 0 0 0.02
                rotation 1 0 0 1.5708
                children [
                  DEF WHEEL_SHAPE Shape {
                    appearance PBRAppearance {
                      baseColor 0.678431 0.847059 0.901961
                      roughness 1
                      metalness 0
                    }
                    geometry Cylinder {
                      height 0.02
                      radius 0.05
                      subdivision 20
                    }
                  }
                ]
              }
            ]
            boundingObject Transform {
              translation 0 0 0.02
              rotation 1 0 0 1.5708
              children [
                DEF wheel1 Shape {
                  appearance PBRAppearance {
                    baseColor 0.8 0.8 0.8
                    transparency 0.12999999523162842
                    roughness 1
                    metalness 0
                    emissiveColor 0 1 0
                  }
                  geometry Cylinder {
                    height 0.02
                    radius 0.05
                  }
                }
              ]
            }
            physics Physics {
            }
          }
        }
      ]
      name "wheel1"
      boundingObject DEF DUMMY Sphere {
        radius 0.01
      }
      physics Physics {
      }
    }
    DEF SOLID2 Solid {
      translation 0 0.02 0
      rotation 0 1 0 0.7854
      children [
        DEF WHEEL2 HingeJoint {
          jointParameters HingeJointParameters {
            position -5.39399906278087e-07
            axis 0 0 -1
            anchor 0 0 0.1
          }
          device [
            RotationalMotor {
              name "wheel2"
              maxVelocity 100
            }
          ]
          endPoint Solid {
            translation 0 0 0.32999999999999946
            rotation 0 0 1 0.0024063494042423626
            children [
              DEF cobo Transform {
                translation 0 0 0.02
                rotation 0 0 1 0.3927003061004253
                children [
                  DEF sr1 HingeJoint {
                    jointParameters HingeJointParameters {
                      position -6.352517592459877e-05
                      anchor 0 0.05 0.02
                    }
                    endPoint Solid {
                      translation 0 0.05 0.02
                      rotation -1 0 0 6.352517242818773e-05
                      children [
                        DEF r1 Transform {
                          rotation 0 0 1 1.5708
                          children [
                            DEF SMALL_WHEEL_SHAPE Shape {
                              appearance PBRAppearance {
                                baseColor 1 0.752941 0.796078
                                roughness 1
                                metalness 0
                              }
                              geometry Cylinder {
                                height 0.02
                                radius 0.01
                              }
                            }
                          ]
                        }
                      ]
                      name "sr1(1)"
                      boundingObject USE r1
                      physics Physics {
                        density -1
                        mass 0.1
                      }
                    }
                  }
                  DEF sr2 HingeJoint {
                    jointParameters HingeJointParameters {
                      position -4.654748554568171e-05
                      axis 0.707107 0.707107 0
                      anchor -0.03535 0.03535 0.02
                    }
                    endPoint Solid {
                      translation -0.03535 0.03535 0.02
                      rotation -0.7071067811865476 -0.7071067811865476 0 4.65474878204196e-05
                      children [
                        DEF r2 Transform {
                          rotation 0 0 1 2.27
                          children [
                            USE SMALL_WHEEL_SHAPE
                          ]
                        }
                      ]
                      name "sr2(1)"
                      boundingObject USE r2
                      physics Physics {
                        density -1
                        mass 0.1
                      }
                    }
                  }
                  DEF sr3 HingeJoint {
                    jointParameters HingeJointParameters {
                      position -0.04103525323229831
                      anchor 0 -0.05 0.02
                    }
                    endPoint Solid {
                      translation 0 -0.05 0.02
                      rotation -1 0 0 0.04103525323229323
                      children [
                        DEF r3 Transform {
                          rotation 0 0 1 1.5708
                          children [
                            USE SMALL_WHEEL_SHAPE
                          ]
                        }
                      ]
                      name "sr3(1)"
                      boundingObject USE r3
                      physics Physics {
                        density -1
                        mass 0.1
                      }
                    }
                  }
                  DEF sr4 HingeJoint {
                    jointParameters HingeJointParameters {
                      position -4.6557209329991446e-05
                      axis 0.707107 0.707107 0
                      anchor 0.03535 -0.03535 0.02
                    }
                    endPoint Solid {
                      translation 0.03535 -0.03535 0.02
                      rotation -0.7071067811865476 -0.7071067811865476 0 4.655720863842534e-05
                      children [
                        DEF r4 Transform {
                          rotation 0 0 1 2.27
                          children [
                            USE SMALL_WHEEL_SHAPE
                          ]
                        }
                      ]
                      name "sr4(1)"
                      boundingObject USE r4
                      physics Physics {
                        density -1
                        mass 0.1
                      }
                    }
                  }
                  DEF sr5 HingeJoint {
                    jointParameters HingeJointParameters {
                      position -2.025100852343402e-06
                      axis 0 1 0
                      anchor -0.05 0 0.02
                    }
                    endPoint Solid {
                      translation -0.05 0 0.02
                      rotation 0 -1 0 2.0250233983230487e-06
                      children [
                        DEF r5 Transform {
                          children [
                            USE SMALL_WHEEL_SHAPE
                          ]
                        }
                      ]
                      name "sr5(1)"
                      boundingObject USE r5
                      physics Physics {
                        density -1
                        mass 0.1
                      }
                    }
                  }
                  DEF sr6 HingeJoint {
                    jointParameters HingeJointParameters {
                      position -2.025101108733244e-06
                      axis 0 1 0
                      anchor 0.05 0 0.02
                    }
                    endPoint Solid {
                      translation 0.05 0 0.02
                      rotation 0 -1 0 2.0250233983230487e-06
                      children [
                        DEF r6 Transform {
                          children [
                            USE SMALL_WHEEL_SHAPE
                          ]
                        }
                      ]
                      name "sr6(1)"
                      boundingObject USE r6
                      physics Physics {
                        density -1
                        mass 0.1
                      }
                    }
                  }
                  DEF sr7 HingeJoint {
                    jointParameters HingeJointParameters {
                      position 4.4894304667585086e-05
                      axis -0.707107 0.707107 0
                      anchor -0.03535 -0.03535 0.02
                    }
                    endPoint Solid {
                      translation -0.03535 -0.03535 0.02
                      rotation -0.7071067811865476 0.7071067811865476 0 4.4894307868471914e-05
                      children [
                        DEF r7 Transform {
                          rotation 0 0 1 0.76
                          children [
                            USE SMALL_WHEEL_SHAPE
                          ]
                        }
                      ]
                      name "sr7(1)"
                      boundingObject USE r7
                      physics Physics {
                        density -1
                        mass 0.1
                      }
                    }
                  }
                  DEF sr8 HingeJoint {
                    jointParameters HingeJointParameters {
                      position 4.488925281233993e-05
                      axis -0.707107 0.707107 0
                      anchor 0.03535 0.03535 0.02
                    }
                    endPoint Solid {
                      translation 0.03535 0.03535 0.02
                      rotation -0.7071067811865476 0.7071067811865476 0 4.488925283201575e-05
                      children [
                        DEF r8 Transform {
                          rotation 0 0 1 0.76
                          children [
                            USE SMALL_WHEEL_SHAPE
                          ]
                        }
                      ]
                      name "sr8(1)"
                      boundingObject USE r8
                      physics Physics {
                        density -1
                        mass 0.1
                      }
                    }
                  }
                  DEF WHEEL_TRANS Transform {
                    translation 0 0 0.02
                    rotation 1 0 0 1.5708
                    children [
                      DEF WHEEL_SHAPE Shape {
                        appearance PBRAppearance {
                          baseColor 0.678431 0.847059 0.901961
                          roughness 1
                          metalness 0
                        }
                        geometry Cylinder {
                          height 0.02
                          radius 0.05
                          subdivision 20
                        }
                      }
                    ]
                  }
                ]
              }
              DEF sr1 HingeJoint {
                jointParameters HingeJointParameters {
                  position -6.163286657193076e-05
                  anchor 0 0.05 0.02
                }
                endPoint Solid {
                  translation 0 0.05 0.02
                  rotation -1 0 0 6.163286716912651e-05
                  children [
                    USE r1
                  ]
                  name "sr1"
                  boundingObject USE r1
                  physics Physics {
                    density -1
                    mass 0.1
                  }
                }
              }
              DEF sr2 HingeJoint {
                jointParameters HingeJointParameters {
                  position -4.509889561820854e-05
                  axis 0.707107 0.707107 0
                  anchor -0.03535 0.03535 0.02
                }
                endPoint Solid {
                  translation -0.03535 0.03535 0.02
                  rotation -0.7071067811865476 -0.7071067811865476 0 4.509890040379118e-05
                  children [
                    USE r2
                  ]
                  name "sr2"
                  boundingObject USE r2
                  physics Physics {
                    density -1
                    mass 0.1
                  }
                }
              }
              DEF sr3 HingeJoint {
                jointParameters HingeJointParameters {
                  position -0.04122809944965921
                  anchor 0 -0.05 0.02
                }
                endPoint Solid {
                  translation 0 -0.05 0.02
                  rotation -1 0 0 0.04122809944965826
                  children [
                    USE r3
                  ]
                  name "sr3"
                  boundingObject USE r3
                  physics Physics {
                    density -1
                    mass 0.1
                  }
                }
              }
              DEF sr4 HingeJoint {
                jointParameters HingeJointParameters {
                  position -4.510764922426375e-05
                  axis 0.707107 0.707107 0
                  anchor 0.03535 -0.03535 0.02
                }
                endPoint Solid {
                  translation 0.03535 -0.03535 0.02
                  rotation -0.7071067811865475 -0.7071067811865475 0 4.510765354400799e-05
                  children [
                    USE r4
                  ]
                  name "sr4"
                  boundingObject USE r4
                  physics Physics {
                    density -1
                    mass 0.1
                  }
                }
              }
              DEF sr5 HingeJoint {
                jointParameters HingeJointParameters {
                  position -1.8708804825569825e-06
                  axis 0 1 0
                  anchor -0.05 0 0.02
                }
                endPoint Solid {
                  translation -0.05 0 0.02
                  rotation 0 -1 0 1.870911850419054e-06
                  children [
                    USE r5
                  ]
                  name "sr5"
                  boundingObject USE r5
                  physics Physics {
                    density -1
                    mass 0.1
                  }
                }
              }
              DEF sr6 HingeJoint {
                jointParameters HingeJointParameters {
                  position -1.8708713106972467e-06
                  axis 0 1 0
                  anchor 0.05 0 0.02
                }
                endPoint Solid {
                  translation 0.05 0 0.02
                  rotation 0 -1 0 1.870911850419054e-06
                  children [
                    USE r6
                  ]
                  name "sr6"
                  boundingObject USE r6
                  physics Physics {
                    density -1
                    mass 0.1
                  }
                }
              }
              DEF sr7 HingeJoint {
                jointParameters HingeJointParameters {
                  position 4.362464925104228e-05
                  axis -0.707107 0.707107 0
                  anchor -0.03535 -0.03535 0.02
                }
                endPoint Solid {
                  translation -0.03535 -0.03535 0.02
                  rotation -0.7071067811865476 0.7071067811865476 0 4.362464521264935e-05
                  children [
                    USE r7
                  ]
                  name "sr7"
                  boundingObject USE r7
                  physics Physics {
                    density -1
                    mass 0.1
                  }
                }
              }
              DEF sr8 HingeJoint {
                jointParameters HingeJointParameters {
                  position 4.361916073499765e-05
                  axis -0.707107 0.707107 0
                  anchor 0.03535 0.03535 0.02
                }
                endPoint Solid {
                  translation 0.03535 0.03535 0.02
                  rotation -0.7071067811865476 0.7071067811865476 0 4.3619157967128084e-05
                  children [
                    USE r8
                  ]
                  name "sr8"
                  boundingObject USE r8
                  physics Physics {
                    density -1
                    mass 0.1
                  }
                }
              }
              USE WHEEL_TRANS
            ]
            boundingObject Transform {
              translation 0 0 0.02
              rotation 1 0 0 1.5708
              children [
                DEF wheel1 Shape {
                  appearance PBRAppearance {
                    baseColor 0.8 0.8 0.8
                    transparency 0.12999999523162842
                    roughness 1
                    metalness 0
                    emissiveColor 0 1 0
                  }
                  geometry Cylinder {
                    height 0.02
                    radius 0.05
                  }
                }
              ]
            }
            physics Physics {
            }
          }
        }
      ]
      name "wheel2"
      boundingObject USE DUMMY
      physics Physics {
        density -1
        mass 5
      }
    }
    DEF SOLID3 Solid {
      translation 0 0.02 0
      rotation 0 1 0 2.3562
      children [
        DEF WHEEL3 HingeJoint {
          jointParameters HingeJointParameters {
            position -8.914817459778847e-07
            axis 0 0 -1
            anchor 0 0 0.1
          }
          device [
            RotationalMotor {
              name "wheel3"
              maxVelocity 100
            }
          ]
          endPoint Solid {
            translation 0 0 0.32999999999999996
            rotation 0 0 1 0.003910331481665535
            children [
              DEF cobo Transform {
                translation 0 0 0.02
                rotation 0 0 1 0.3927003061004253
                children [
                  DEF sr1 HingeJoint {
                    jointParameters HingeJointParameters {
                      position -6.352517592459877e-05
                      anchor 0 0.05 0.02
                    }
                    endPoint Solid {
                      translation 0 0.05 0.02
                      rotation -1 0 0 6.352517242818773e-05
                      children [
                        DEF r1 Transform {
                          rotation 0 0 1 1.5708
                          children [
                            DEF SMALL_WHEEL_SHAPE Shape {
                              appearance PBRAppearance {
                                baseColor 1 0.752941 0.796078
                                roughness 1
                                metalness 0
                              }
                              geometry Cylinder {
                                height 0.02
                                radius 0.01
                              }
                            }
                          ]
                        }
                      ]
                      name "sr1(1)"
                      boundingObject USE r1
                      physics Physics {
                        density -1
                        mass 0.1
                      }
                    }
                  }
                  DEF sr2 HingeJoint {
                    jointParameters HingeJointParameters {
                      position -4.654748554568171e-05
                      axis 0.707107 0.707107 0
                      anchor -0.03535 0.03535 0.02
                    }
                    endPoint Solid {
                      translation -0.03535 0.03535 0.02
                      rotation -0.7071067811865476 -0.7071067811865476 0 4.65474878204196e-05
                      children [
                        DEF r2 Transform {
                          rotation 0 0 1 2.27
                          children [
                            USE SMALL_WHEEL_SHAPE
                          ]
                        }
                      ]
                      name "sr2(1)"
                      boundingObject USE r2
                      physics Physics {
                        density -1
                        mass 0.1
                      }
                    }
                  }
                  DEF sr3 HingeJoint {
                    jointParameters HingeJointParameters {
                      position -0.04103525323229831
                      anchor 0 -0.05 0.02
                    }
                    endPoint Solid {
                      translation 0 -0.05 0.02
                      rotation -1 0 0 0.04103525323229323
                      children [
                        DEF r3 Transform {
                          rotation 0 0 1 1.5708
                          children [
                            USE SMALL_WHEEL_SHAPE
                          ]
                        }
                      ]
                      name "sr3(1)"
                      boundingObject USE r3
                      physics Physics {
                        density -1
                        mass 0.1
                      }
                    }
                  }
                  DEF sr4 HingeJoint {
                    jointParameters HingeJointParameters {
                      position -4.6557209329991446e-05
                      axis 0.707107 0.707107 0
                      anchor 0.03535 -0.03535 0.02
                    }
                    endPoint Solid {
                      translation 0.03535 -0.03535 0.02
                      rotation -0.7071067811865476 -0.7071067811865476 0 4.655720863842534e-05
                      children [
                        DEF r4 Transform {
                          rotation 0 0 1 2.27
                          children [
                            USE SMALL_WHEEL_SHAPE
                          ]
                        }
                      ]
                      name "sr4(1)"
                      boundingObject USE r4
                      physics Physics {
                        density -1
                        mass 0.1
                      }
                    }
                  }
                  DEF sr5 HingeJoint {
                    jointParameters HingeJointParameters {
                      position -2.025100852343402e-06
                      axis 0 1 0
                      anchor -0.05 0 0.02
                    }
                    endPoint Solid {
                      translation -0.05 0 0.02
                      rotation 0 -1 0 2.0250233983230487e-06
                      children [
                        DEF r5 Transform {
                          children [
                            USE SMALL_WHEEL_SHAPE
                          ]
                        }
                      ]
                      name "sr5(1)"
                      boundingObject USE r5
                      physics Physics {
                        density -1
                        mass 0.1
                      }
                    }
                  }
                  DEF sr6 HingeJoint {
                    jointParameters HingeJointParameters {
                      position -2.025101108733244e-06
                      axis 0 1 0
                      anchor 0.05 0 0.02
                    }
                    endPoint Solid {
                      translation 0.05 0 0.02
                      rotation 0 -1 0 2.0250233983230487e-06
                      children [
                        DEF r6 Transform {
                          children [
                            USE SMALL_WHEEL_SHAPE
                          ]
                        }
                      ]
                      name "sr6(1)"
                      boundingObject USE r6
                      physics Physics {
                        density -1
                        mass 0.1
                      }
                    }
                  }
                  DEF sr7 HingeJoint {
                    jointParameters HingeJointParameters {
                      position 4.4894304667585086e-05
                      axis -0.707107 0.707107 0
                      anchor -0.03535 -0.03535 0.02
                    }
                    endPoint Solid {
                      translation -0.03535 -0.03535 0.02
                      rotation -0.7071067811865476 0.7071067811865476 0 4.4894307868471914e-05
                      children [
                        DEF r7 Transform {
                          rotation 0 0 1 0.76
                          children [
                            USE SMALL_WHEEL_SHAPE
                          ]
                        }
                      ]
                      name "sr7(1)"
                      boundingObject USE r7
                      physics Physics {
                        density -1
                        mass 0.1
                      }
                    }
                  }
                  DEF sr8 HingeJoint {
                    jointParameters HingeJointParameters {
                      position 4.488925281233993e-05
                      axis -0.707107 0.707107 0
                      anchor 0.03535 0.03535 0.02
                    }
                    endPoint Solid {
                      translation 0.03535 0.03535 0.02
                      rotation -0.7071067811865476 0.7071067811865476 0 4.488925283201575e-05
                      children [
                        DEF r8 Transform {
                          rotation 0 0 1 0.76
                          children [
                            USE SMALL_WHEEL_SHAPE
                          ]
                        }
                      ]
                      name "sr8(1)"
                      boundingObject USE r8
                      physics Physics {
                        density -1
                        mass 0.1
                      }
                    }
                  }
                  DEF WHEEL_TRANS Transform {
                    translation 0 0 0.02
                    rotation 1 0 0 1.5708
                    children [
                      DEF WHEEL_SHAPE Shape {
                        appearance PBRAppearance {
                          baseColor 0.678431 0.847059 0.901961
                          roughness 1
                          metalness 0
                        }
                        geometry Cylinder {
                          height 0.02
                          radius 0.05
                          subdivision 20
                        }
                      }
                    ]
                  }
                ]
              }
              DEF sr1 HingeJoint {
                jointParameters HingeJointParameters {
                  position 7.045115215217092e-05
                  anchor 0 0.05 0.02
                }
                endPoint Solid {
                  translation 0 0.05 0.02
                  rotation 1 0 0 7.045115208965212e-05
                  children [
                    USE r1
                  ]
                  name "sr1"
                  boundingObject USE r1
                  physics Physics {
                    density -1
                    mass 0.1
                  }
                }
              }
              DEF sr2 HingeJoint {
                jointParameters HingeJointParameters {
                  position 4.919253025391545e-05
                  axis 0.707107 0.707107 0
                  anchor -0.03535 0.03535 0.02
                }
                endPoint Solid {
                  translation -0.03535 0.03535 0.02
                  rotation 0.7071067811865476 0.7071067811865476 0 4.9192531600465416e-05
                  children [
                    USE r2
                  ]
                  name "sr2"
                  boundingObject USE r2
                  physics Physics {
                    density -1
                    mass 0.1
                  }
                }
              }
              DEF sr3 HingeJoint {
                jointParameters HingeJointParameters {
                  position 0.04076335533159047
                  anchor 0 -0.05 0.02
                }
                endPoint Solid {
                  translation 0 -0.05 0.02
                  rotation 1 0 0 0.04076335533158513
                  children [
                    USE r3
                  ]
                  name "sr3"
                  boundingObject USE r3
                  physics Physics {
                    density -1
                    mass 0.1
                  }
                }
              }
              DEF sr4 HingeJoint {
                jointParameters HingeJointParameters {
                  position 4.92034642158626e-05
                  axis 0.707107 0.707107 0
                  anchor 0.03535 -0.03535 0.02
                }
                endPoint Solid {
                  translation 0.03535 -0.03535 0.02
                  rotation 0.7071067811865476 0.7071067811865476 0 4.920346277782849e-05
                  children [
                    USE r4
                  ]
                  name "sr4"
                  boundingObject USE r4
                  physics Physics {
                    density -1
                    mass 0.1
                  }
                }
              }
              DEF sr5 HingeJoint {
                jointParameters HingeJointParameters {
                  position -2.3192470818453628e-06
                  axis 0 1 0
                  anchor -0.05 0 0.02
                }
                endPoint Solid {
                  translation -0.05 0 0.02
                  rotation 0 -1 0 2.319225842755414e-06
                  children [
                    USE r5
                  ]
                  name "sr5"
                  boundingObject USE r5
                  physics Physics {
                    density -1
                    mass 0.1
                  }
                }
              }
              DEF sr6 HingeJoint {
                jointParameters HingeJointParameters {
                  position -2.319225398234896e-06
                  axis 0 1 0
                  anchor 0.05 0 0.02
                }
                endPoint Solid {
                  translation 0.05 0 0.02
                  rotation 0 -1 0 2.319225842755414e-06
                  children [
                    USE r6
                  ]
                  name "sr6"
                  boundingObject USE r6
                  physics Physics {
                    density -1
                    mass 0.1
                  }
                }
              }
              DEF sr7 HingeJoint {
                jointParameters HingeJointParameters {
                  position -5.295170708802413e-05
                  axis -0.707107 0.707107 0
                  anchor -0.03535 -0.03535 0.02
                }
                endPoint Solid {
                  translation -0.03535 -0.03535 0.02
                  rotation 0.7071067811865475 -0.7071067811865475 0 5.2951707695670723e-05
                  children [
                    USE r7
                  ]
                  name "sr7"
                  boundingObject USE r7
                  physics Physics {
                    density -1
                    mass 0.1
                  }
                }
              }
              DEF sr8 HingeJoint {
                jointParameters HingeJointParameters {
                  position -5.2935961029567206e-05
                  axis -0.707107 0.707107 0
                  anchor 0.03535 0.03535 0.02
                }
                endPoint Solid {
                  translation 0.03535 0.03535 0.02
                  rotation 0.7071067811865476 -0.7071067811865476 0 5.2935963550253644e-05
                  children [
                    USE r8
                  ]
                  name "sr8"
                  boundingObject USE r8
                  physics Physics {
                    density -1
                    mass 0.1
                  }
                }
              }
              USE WHEEL_TRANS
            ]
            boundingObject Transform {
              translation 0 0 0.02
              rotation 1 0 0 1.5708
              children [
                DEF wheel1 Shape {
                  appearance PBRAppearance {
                    baseColor 0.8 0.8 0.8
                    transparency 0.12999999523162842
                    roughness 1
                    metalness 0
                    emissiveColor 0 1 0
                  }
                  geometry Cylinder {
                    height 0.02
                    radius 0.05
                  }
                }
              ]
            }
            physics Physics {
            }
          }
        }
      ]
      name "wheel3"
      boundingObject USE DUMMY
      physics Physics {
        density -1
        mass 5
      }
    }
    DEF SOLID4 Solid {
      translation 0 0.02 0
      rotation 0 1 0 3.927
      children [
        DEF WHEEL3 HingeJoint {
          jointParameters HingeJointParameters {
            position -8.57244196154083e-07
            axis 0 0 -1
            anchor 0 0 0.1
          }
          device [
            RotationalMotor {
              name "wheel4"
              maxVelocity 100
            }
          ]
          endPoint Solid {
            translation 0 0 0.33000000000000057
            rotation 0 0 1 0.003910297244096131
            children [
              DEF cobo Transform {
                translation 0 0 0.02
                rotation 0 0 1 0.3927003061004253
                children [
                  DEF sr1 HingeJoint {
                    jointParameters HingeJointParameters {
                      position -6.352517592459877e-05
                      anchor 0 0.05 0.02
                    }
                    endPoint Solid {
                      translation 0 0.05 0.02
                      rotation -1 0 0 6.352517242818773e-05
                      children [
                        DEF r1 Transform {
                          rotation 0 0 1 1.5708
                          children [
                            DEF SMALL_WHEEL_SHAPE Shape {
                              appearance PBRAppearance {
                                baseColor 1 0.752941 0.796078
                                roughness 1
                                metalness 0
                              }
                              geometry Cylinder {
                                height 0.02
                                radius 0.01
                              }
                            }
                          ]
                        }
                      ]
                      name "sr1(1)"
                      boundingObject USE r1
                      physics Physics {
                        density -1
                        mass 0.1
                      }
                    }
                  }
                  DEF sr2 HingeJoint {
                    jointParameters HingeJointParameters {
                      position -4.654748554568171e-05
                      axis 0.707107 0.707107 0
                      anchor -0.03535 0.03535 0.02
                    }
                    endPoint Solid {
                      translation -0.03535 0.03535 0.02
                      rotation -0.7071067811865476 -0.7071067811865476 0 4.65474878204196e-05
                      children [
                        DEF r2 Transform {
                          rotation 0 0 1 2.27
                          children [
                            USE SMALL_WHEEL_SHAPE
                          ]
                        }
                      ]
                      name "sr2(1)"
                      boundingObject USE r2
                      physics Physics {
                        density -1
                        mass 0.1
                      }
                    }
                  }
                  DEF sr3 HingeJoint {
                    jointParameters HingeJointParameters {
                      position -0.04103525323229831
                      anchor 0 -0.05 0.02
                    }
                    endPoint Solid {
                      translation 0 -0.05 0.02
                      rotation -1 0 0 0.04103525323229323
                      children [
                        DEF r3 Transform {
                          rotation 0 0 1 1.5708
                          children [
                            USE SMALL_WHEEL_SHAPE
                          ]
                        }
                      ]
                      name "sr3(1)"
                      boundingObject USE r3
                      physics Physics {
                        density -1
                        mass 0.1
                      }
                    }
                  }
                  DEF sr4 HingeJoint {
                    jointParameters HingeJointParameters {
                      position -4.6557209329991446e-05
                      axis 0.707107 0.707107 0
                      anchor 0.03535 -0.03535 0.02
                    }
                    endPoint Solid {
                      translation 0.03535 -0.03535 0.02
                      rotation -0.7071067811865476 -0.7071067811865476 0 4.655720863842534e-05
                      children [
                        DEF r4 Transform {
                          rotation 0 0 1 2.27
                          children [
                            USE SMALL_WHEEL_SHAPE
                          ]
                        }
                      ]
                      name "sr4(1)"
                      boundingObject USE r4
                      physics Physics {
                        density -1
                        mass 0.1
                      }
                    }
                  }
                  DEF sr5 HingeJoint {
                    jointParameters HingeJointParameters {
                      position -2.025100852343402e-06
                      axis 0 1 0
                      anchor -0.05 0 0.02
                    }
                    endPoint Solid {
                      translation -0.05 0 0.02
                      rotation 0 -1 0 2.0250233983230487e-06
                      children [
                        DEF r5 Transform {
                          children [
                            USE SMALL_WHEEL_SHAPE
                          ]
                        }
                      ]
                      name "sr5(1)"
                      boundingObject USE r5
                      physics Physics {
                        density -1
                        mass 0.1
                      }
                    }
                  }
                  DEF sr6 HingeJoint {
                    jointParameters HingeJointParameters {
                      position -2.025101108733244e-06
                      axis 0 1 0
                      anchor 0.05 0 0.02
                    }
                    endPoint Solid {
                      translation 0.05 0 0.02
                      rotation 0 -1 0 2.0250233983230487e-06
                      children [
                        DEF r6 Transform {
                          children [
                            USE SMALL_WHEEL_SHAPE
                          ]
                        }
                      ]
                      name "sr6(1)"
                      boundingObject USE r6
                      physics Physics {
                        density -1
                        mass 0.1
                      }
                    }
                  }
                  DEF sr7 HingeJoint {
                    jointParameters HingeJointParameters {
                      position 4.4894304667585086e-05
                      axis -0.707107 0.707107 0
                      anchor -0.03535 -0.03535 0.02
                    }
                    endPoint Solid {
                      translation -0.03535 -0.03535 0.02
                      rotation -0.7071067811865476 0.7071067811865476 0 4.4894307868471914e-05
                      children [
                        DEF r7 Transform {
                          rotation 0 0 1 0.76
                          children [
                            USE SMALL_WHEEL_SHAPE
                          ]
                        }
                      ]
                      name "sr7(1)"
                      boundingObject USE r7
                      physics Physics {
                        density -1
                        mass 0.1
                      }
                    }
                  }
                  DEF sr8 HingeJoint {
                    jointParameters HingeJointParameters {
                      position 4.488925281233993e-05
                      axis -0.707107 0.707107 0
                      anchor 0.03535 0.03535 0.02
                    }
                    endPoint Solid {
                      translation 0.03535 0.03535 0.02
                      rotation -0.7071067811865476 0.7071067811865476 0 4.488925283201575e-05
                      children [
                        DEF r8 Transform {
                          rotation 0 0 1 0.76
                          children [
                            USE SMALL_WHEEL_SHAPE
                          ]
                        }
                      ]
                      name "sr8(1)"
                      boundingObject USE r8
                      physics Physics {
                        density -1
                        mass 0.1
                      }
                    }
                  }
                  DEF WHEEL_TRANS Transform {
                    translation 0 0 0.02
                    rotation 1 0 0 1.5708
                    children [
                      DEF WHEEL_SHAPE Shape {
                        appearance PBRAppearance {
                          baseColor 0.678431 0.847059 0.901961
                          roughness 1
                          metalness 0
                        }
                        geometry Cylinder {
                          height 0.02
                          radius 0.05
                          subdivision 20
                        }
                      }
                    ]
                  }
                ]
              }
              DEF sr1 HingeJoint {
                jointParameters HingeJointParameters {
                  position 6.855155662769949e-05
                  anchor 0 0.05 0.02
                }
                endPoint Solid {
                  translation 0 0.05 0.02
                  rotation 1 0 0 6.855155434983389e-05
                  children [
                    USE r1
                  ]
                  name "sr1"
                  boundingObject USE r1
                  physics Physics {
                    density -1
                    mass 0.1
                  }
                }
              }
              DEF sr2 HingeJoint {
                jointParameters HingeJointParameters {
                  position 4.784558576112845e-05
                  axis 0.707107 0.707107 0
                  anchor -0.03535 0.03535 0.02
                }
                endPoint Solid {
                  translation -0.03535 0.03535 0.02
                  rotation 0.7071067811865476 0.7071067811865476 0 4.784558433992081e-05
                  children [
                    USE r2
                  ]
                  name "sr2"
                  boundingObject USE r2
                  physics Physics {
                    density -1
                    mass 0.1
                  }
                }
              }
              DEF sr3 HingeJoint {
                jointParameters HingeJointParameters {
                  position 0.04076353992558737
                  anchor 0 -0.05 0.02
                }
                endPoint Solid {
                  translation 0 -0.05 0.02
                  rotation 1 0 0 0.0407635399255896
                  children [
                    USE r3
                  ]
                  name "sr3"
                  boundingObject USE r3
                  physics Physics {
                    density -1
                    mass 0.1
                  }
                }
              }
              DEF sr4 HingeJoint {
                jointParameters HingeJointParameters {
                  position 4.7856910677504344e-05
                  axis 0.707107 0.707107 0
                  anchor 0.03535 -0.03535 0.02
                }
                endPoint Solid {
                  translation 0.03535 -0.03535 0.02
                  rotation 0.7071067811865475 0.7071067811865475 0 4.785690669590559e-05
                  children [
                    USE r4
                  ]
                  name "sr4"
                  boundingObject USE r4
                  physics Physics {
                    density -1
                    mass 0.1
                  }
                }
              }
              DEF sr5 HingeJoint {
                jointParameters HingeJointParameters {
                  position -2.311095180342723e-06
                  axis 0 1 0
                  anchor -0.05 0 0.02
                }
                endPoint Solid {
                  translation -0.05 0 0.02
                  rotation 0 -1 0 2.311169620793149e-06
                  children [
                    USE r5
                  ]
                  name "sr5"
                  boundingObject USE r5
                  physics Physics {
                    density -1
                    mass 0.1
                  }
                }
              }
              DEF sr6 HingeJoint {
                jointParameters HingeJointParameters {
                  position -2.3110803211682253e-06
                  axis 0 1 0
                  anchor 0.05 0 0.02
                }
                endPoint Solid {
                  translation 0.05 0 0.02
                  rotation 0 -1 0 2.311169620793149e-06
                  children [
                    USE r6
                  ]
                  name "sr6"
                  boundingObject USE r6
                  physics Physics {
                    density -1
                    mass 0.1
                  }
                }
              }
              DEF sr7 HingeJoint {
                jointParameters HingeJointParameters {
                  position -5.156923879075319e-05
                  axis -0.707107 0.707107 0
                  anchor -0.03535 -0.03535 0.02
                }
                endPoint Solid {
                  translation -0.03535 -0.03535 0.02
                  rotation 0.7071067811865476 -0.7071067811865476 0 5.156923975538823e-05
                  children [
                    USE r7
                  ]
                  name "sr7"
                  boundingObject USE r7
                  physics Physics {
                    density -1
                    mass 0.1
                  }
                }
              }
              DEF sr8 HingeJoint {
                jointParameters HingeJointParameters {
                  position -5.1554554617405903e-05
                  axis -0.707107 0.707107 0
                  anchor 0.03535 0.03535 0.02
                }
                endPoint Solid {
                  translation 0.03535 0.03535 0.02
                  rotation 0.7071067811865476 -0.7071067811865476 0 5.155455503389548e-05
                  children [
                    USE r8
                  ]
                  name "sr8"
                  boundingObject USE r8
                  physics Physics {
                    density -1
                    mass 0.1
                  }
                }
              }
              USE WHEEL_TRANS
            ]
            boundingObject Transform {
              translation 0 0 0.02
              rotation 1 0 0 1.5708
              children [
                DEF wheel1 Shape {
                  appearance PBRAppearance {
                    baseColor 0.8 0.8 0.8
                    transparency 0.12999999523162842
                    roughness 1
                    metalness 0
                    emissiveColor 0 1 0
                  }
                  geometry Cylinder {
                    height 0.02
                    radius 0.05
                  }
                }
              ]
            }
            physics Physics {
            }
          }
        }
      ]
      name "wheel4"
      boundingObject USE DUMMY
      physics Physics {
        density -1
        mass 5
      }
    }
  ]
  name "four"
  boundingObject USE RealBaseShape
  physics Physics {
  }
  controller "four_wheels"
  supervisor TRUE
}
